[2025-05-03T21:37:32.226+0000] {taskinstance.py:1157} INFO - Dependencies all met for dep_context=non-requeueable deps ti=<TaskInstance: gold_pipeline.extract_gold_data manual__2025-05-03T21:37:28.998636+00:00 [queued]>
[2025-05-03T21:37:32.238+0000] {taskinstance.py:1157} INFO - Dependencies all met for dep_context=requeueable deps ti=<TaskInstance: gold_pipeline.extract_gold_data manual__2025-05-03T21:37:28.998636+00:00 [queued]>
[2025-05-03T21:37:32.239+0000] {taskinstance.py:1359} INFO - Starting attempt 1 of 1
[2025-05-03T21:37:32.254+0000] {taskinstance.py:1380} INFO - Executing <Task(PythonOperator): extract_gold_data> on 2025-05-03 21:37:28.998636+00:00
[2025-05-03T21:37:32.263+0000] {standard_task_runner.py:57} INFO - Started process 484 to run task
[2025-05-03T21:37:32.267+0000] {standard_task_runner.py:84} INFO - Running: ['***', 'tasks', 'run', 'gold_pipeline', 'extract_gold_data', 'manual__2025-05-03T21:37:28.998636+00:00', '--job-id', '4', '--raw', '--subdir', 'DAGS_FOLDER/pipeline.py', '--cfg-path', '/tmp/tmp4gjvynkt']
[2025-05-03T21:37:32.271+0000] {standard_task_runner.py:85} INFO - Job 4: Subtask extract_gold_data
[2025-05-03T21:37:32.348+0000] {task_command.py:415} INFO - Running <TaskInstance: gold_pipeline.extract_gold_data manual__2025-05-03T21:37:28.998636+00:00 [running]> on host 889058e2ea92
[2025-05-03T21:37:32.510+0000] {taskinstance.py:1660} INFO - Exporting env vars: AIRFLOW_CTX_DAG_OWNER='***' AIRFLOW_CTX_DAG_ID='gold_pipeline' AIRFLOW_CTX_TASK_ID='extract_gold_data' AIRFLOW_CTX_EXECUTION_DATE='2025-05-03T21:37:28.998636+00:00' AIRFLOW_CTX_TRY_NUMBER='1' AIRFLOW_CTX_DAG_RUN_ID='manual__2025-05-03T21:37:28.998636+00:00'
[2025-05-03T21:37:32.952+0000] {taskinstance.py:1935} ERROR - Task failed with exception
Traceback (most recent call last):
  File "/home/airflow/.local/lib/python3.8/site-packages/airflow/operators/python.py", line 192, in execute
    return_value = self.execute_callable()
  File "/home/airflow/.local/lib/python3.8/site-packages/airflow/operators/python.py", line 209, in execute_callable
    return self.python_callable(*self.op_args, **self.op_kwargs)
  File "/opt/airflow/dags/extract_gold.py", line 18, in extract_gold_data
    raise ValueError("Erreur Alpha Vantage: 'Time Series (240min)' non trouvé. Vérifiez la clé API ou la réponse.")
ValueError: Erreur Alpha Vantage: 'Time Series (240min)' non trouvé. Vérifiez la clé API ou la réponse.
[2025-05-03T21:37:32.973+0000] {taskinstance.py:1398} INFO - Marking task as FAILED. dag_id=gold_pipeline, task_id=extract_gold_data, execution_date=20250503T213728, start_date=20250503T213732, end_date=20250503T213732
[2025-05-03T21:37:33.000+0000] {standard_task_runner.py:104} ERROR - Failed to execute job 4 for task extract_gold_data (Erreur Alpha Vantage: 'Time Series (240min)' non trouvé. Vérifiez la clé API ou la réponse.; 484)
[2025-05-03T21:37:33.042+0000] {local_task_job_runner.py:228} INFO - Task exited with return code 1
[2025-05-03T21:37:33.075+0000] {taskinstance.py:2776} INFO - 0 downstream tasks scheduled from follow-on schedule check
