[2025-05-03T21:33:13.729+0000] {taskinstance.py:1157} INFO - Dependencies all met for dep_context=non-requeueable deps ti=<TaskInstance: gold_pipeline.extract_gold_data manual__2025-05-03T21:33:09.543006+00:00 [queued]>
[2025-05-03T21:33:13.744+0000] {taskinstance.py:1157} INFO - Dependencies all met for dep_context=requeueable deps ti=<TaskInstance: gold_pipeline.extract_gold_data manual__2025-05-03T21:33:09.543006+00:00 [queued]>
[2025-05-03T21:33:13.746+0000] {taskinstance.py:1359} INFO - Starting attempt 1 of 1
[2025-05-03T21:33:13.769+0000] {taskinstance.py:1380} INFO - Executing <Task(PythonOperator): extract_gold_data> on 2025-05-03 21:33:09.543006+00:00
[2025-05-03T21:33:13.780+0000] {standard_task_runner.py:57} INFO - Started process 290 to run task
[2025-05-03T21:33:13.784+0000] {standard_task_runner.py:84} INFO - Running: ['***', 'tasks', 'run', 'gold_pipeline', 'extract_gold_data', 'manual__2025-05-03T21:33:09.543006+00:00', '--job-id', '3', '--raw', '--subdir', 'DAGS_FOLDER/pipeline.py', '--cfg-path', '/tmp/tmpvfifs4pe']
[2025-05-03T21:33:13.787+0000] {standard_task_runner.py:85} INFO - Job 3: Subtask extract_gold_data
[2025-05-03T21:33:13.862+0000] {task_command.py:415} INFO - Running <TaskInstance: gold_pipeline.extract_gold_data manual__2025-05-03T21:33:09.543006+00:00 [running]> on host 889058e2ea92
[2025-05-03T21:33:14.008+0000] {taskinstance.py:1660} INFO - Exporting env vars: AIRFLOW_CTX_DAG_OWNER='***' AIRFLOW_CTX_DAG_ID='gold_pipeline' AIRFLOW_CTX_TASK_ID='extract_gold_data' AIRFLOW_CTX_EXECUTION_DATE='2025-05-03T21:33:09.543006+00:00' AIRFLOW_CTX_TRY_NUMBER='1' AIRFLOW_CTX_DAG_RUN_ID='manual__2025-05-03T21:33:09.543006+00:00'
[2025-05-03T21:33:14.543+0000] {taskinstance.py:1935} ERROR - Task failed with exception
Traceback (most recent call last):
  File "/home/airflow/.local/lib/python3.8/site-packages/airflow/operators/python.py", line 192, in execute
    return_value = self.execute_callable()
  File "/home/airflow/.local/lib/python3.8/site-packages/airflow/operators/python.py", line 209, in execute_callable
    return self.python_callable(*self.op_args, **self.op_kwargs)
  File "/opt/airflow/dags/extract_gold.py", line 17, in extract_gold_data
    gold_data = pd.DataFrame(response.json()["Time Series (4h)"]).T
KeyError: 'Time Series (4h)'
[2025-05-03T21:33:14.577+0000] {taskinstance.py:1398} INFO - Marking task as FAILED. dag_id=gold_pipeline, task_id=extract_gold_data, execution_date=20250503T213309, start_date=20250503T213313, end_date=20250503T213314
[2025-05-03T21:33:14.608+0000] {standard_task_runner.py:104} ERROR - Failed to execute job 3 for task extract_gold_data ('Time Series (4h)'; 290)
[2025-05-03T21:33:14.640+0000] {local_task_job_runner.py:228} INFO - Task exited with return code 1
[2025-05-03T21:33:14.671+0000] {taskinstance.py:2776} INFO - 0 downstream tasks scheduled from follow-on schedule check
