[2025-05-08T13:24:11.360+0000] {taskinstance.py:1157} INFO - Dependencies all met for dep_context=non-requeueable deps ti=<TaskInstance: gold_pipeline.transform_gold_data manual__2025-05-08T13:23:32.872283+00:00 [queued]>
[2025-05-08T13:24:11.370+0000] {taskinstance.py:1157} INFO - Dependencies all met for dep_context=requeueable deps ti=<TaskInstance: gold_pipeline.transform_gold_data manual__2025-05-08T13:23:32.872283+00:00 [queued]>
[2025-05-08T13:24:11.371+0000] {taskinstance.py:1359} INFO - Starting attempt 1 of 1
[2025-05-08T13:24:11.387+0000] {taskinstance.py:1380} INFO - Executing <Task(PythonOperator): transform_gold_data> on 2025-05-08 13:23:32.872283+00:00
[2025-05-08T13:24:11.393+0000] {standard_task_runner.py:57} INFO - Started process 415 to run task
[2025-05-08T13:24:11.398+0000] {standard_task_runner.py:84} INFO - Running: ['***', 'tasks', 'run', 'gold_pipeline', 'transform_gold_data', 'manual__2025-05-08T13:23:32.872283+00:00', '--job-id', '15', '--raw', '--subdir', 'DAGS_FOLDER/pipeline.py', '--cfg-path', '/tmp/tmpw_ce_dtt']
[2025-05-08T13:24:11.404+0000] {standard_task_runner.py:85} INFO - Job 15: Subtask transform_gold_data
[2025-05-08T13:24:11.454+0000] {task_command.py:415} INFO - Running <TaskInstance: gold_pipeline.transform_gold_data manual__2025-05-08T13:23:32.872283+00:00 [running]> on host 223a2d167166
[2025-05-08T13:24:11.536+0000] {taskinstance.py:1660} INFO - Exporting env vars: AIRFLOW_CTX_DAG_OWNER='***' AIRFLOW_CTX_DAG_ID='gold_pipeline' AIRFLOW_CTX_TASK_ID='transform_gold_data' AIRFLOW_CTX_EXECUTION_DATE='2025-05-08T13:23:32.872283+00:00' AIRFLOW_CTX_TRY_NUMBER='1' AIRFLOW_CTX_DAG_RUN_ID='manual__2025-05-08T13:23:32.872283+00:00'
[2025-05-08T13:24:11.541+0000] {taskinstance.py:1935} ERROR - Task failed with exception
Traceback (most recent call last):
  File "/home/airflow/.local/lib/python3.8/site-packages/airflow/operators/python.py", line 192, in execute
    return_value = self.execute_callable()
  File "/home/airflow/.local/lib/python3.8/site-packages/airflow/operators/python.py", line 209, in execute_callable
    return self.python_callable(*self.op_args, **self.op_kwargs)
  File "/opt/airflow/dags/transform.py", line 13, in transform_gold_data
    gold_df = pd.read_csv(HDFS_CLIENT.read(f"/gold_datalake/raw/gold_prices/{today}.csv"))
  File "/home/airflow/.local/lib/python3.8/site-packages/pandas/io/parsers/readers.py", line 912, in read_csv
    return _read(filepath_or_buffer, kwds)
  File "/home/airflow/.local/lib/python3.8/site-packages/pandas/io/parsers/readers.py", line 577, in _read
    parser = TextFileReader(filepath_or_buffer, **kwds)
  File "/home/airflow/.local/lib/python3.8/site-packages/pandas/io/parsers/readers.py", line 1407, in __init__
    self._engine = self._make_engine(f, self.engine)
  File "/home/airflow/.local/lib/python3.8/site-packages/pandas/io/parsers/readers.py", line 1661, in _make_engine
    self.handles = get_handle(
  File "/home/airflow/.local/lib/python3.8/site-packages/pandas/io/common.py", line 716, in get_handle
    ioargs = _get_filepath_or_buffer(
  File "/home/airflow/.local/lib/python3.8/site-packages/pandas/io/common.py", line 456, in _get_filepath_or_buffer
    raise ValueError(msg)
ValueError: Invalid file path or buffer object type: <class 'contextlib._GeneratorContextManager'>
[2025-05-08T13:24:11.555+0000] {taskinstance.py:1398} INFO - Marking task as FAILED. dag_id=gold_pipeline, task_id=transform_gold_data, execution_date=20250508T132332, start_date=20250508T132411, end_date=20250508T132411
[2025-05-08T13:24:11.572+0000] {standard_task_runner.py:104} ERROR - Failed to execute job 15 for task transform_gold_data (Invalid file path or buffer object type: <class 'contextlib._GeneratorContextManager'>; 415)
[2025-05-08T13:24:11.611+0000] {local_task_job_runner.py:228} INFO - Task exited with return code 1
[2025-05-08T13:24:11.635+0000] {taskinstance.py:2776} INFO - 0 downstream tasks scheduled from follow-on schedule check
