[2025-05-03T21:55:09.683+0000] {taskinstance.py:1157} INFO - Dependencies all met for dep_context=non-requeueable deps ti=<TaskInstance: gold_pipeline.transform_gold_data manual__2025-05-03T21:54:37.179681+00:00 [queued]>
[2025-05-03T21:55:09.691+0000] {taskinstance.py:1157} INFO - Dependencies all met for dep_context=requeueable deps ti=<TaskInstance: gold_pipeline.transform_gold_data manual__2025-05-03T21:54:37.179681+00:00 [queued]>
[2025-05-03T21:55:09.692+0000] {taskinstance.py:1359} INFO - Starting attempt 1 of 1
[2025-05-03T21:55:09.707+0000] {taskinstance.py:1380} INFO - Executing <Task(PythonOperator): transform_gold_data> on 2025-05-03 21:54:37.179681+00:00
[2025-05-03T21:55:09.716+0000] {standard_task_runner.py:57} INFO - Started process 1716 to run task
[2025-05-03T21:55:09.719+0000] {standard_task_runner.py:84} INFO - Running: ['***', 'tasks', 'run', 'gold_pipeline', 'transform_gold_data', 'manual__2025-05-03T21:54:37.179681+00:00', '--job-id', '12', '--raw', '--subdir', 'DAGS_FOLDER/pipeline.py', '--cfg-path', '/tmp/tmpco_a246d']
[2025-05-03T21:55:09.723+0000] {standard_task_runner.py:85} INFO - Job 12: Subtask transform_gold_data
[2025-05-03T21:55:09.773+0000] {task_command.py:415} INFO - Running <TaskInstance: gold_pipeline.transform_gold_data manual__2025-05-03T21:54:37.179681+00:00 [running]> on host 889058e2ea92
[2025-05-03T21:55:09.877+0000] {taskinstance.py:1660} INFO - Exporting env vars: AIRFLOW_CTX_DAG_OWNER='***' AIRFLOW_CTX_DAG_ID='gold_pipeline' AIRFLOW_CTX_TASK_ID='transform_gold_data' AIRFLOW_CTX_EXECUTION_DATE='2025-05-03T21:54:37.179681+00:00' AIRFLOW_CTX_TRY_NUMBER='1' AIRFLOW_CTX_DAG_RUN_ID='manual__2025-05-03T21:54:37.179681+00:00'
[2025-05-03T21:55:09.884+0000] {taskinstance.py:1935} ERROR - Task failed with exception
Traceback (most recent call last):
  File "/home/airflow/.local/lib/python3.8/site-packages/airflow/operators/python.py", line 192, in execute
    return_value = self.execute_callable()
  File "/home/airflow/.local/lib/python3.8/site-packages/airflow/operators/python.py", line 209, in execute_callable
    return self.python_callable(*self.op_args, **self.op_kwargs)
  File "/opt/airflow/dags/transform.py", line 13, in transform_gold_data
    gold_df = pd.read_csv(HDFS_CLIENT.read(f"/gold_datalake/raw/gold_prices/{today}.csv"))
  File "/home/airflow/.local/lib/python3.8/site-packages/pandas/io/parsers/readers.py", line 912, in read_csv
    return _read(filepath_or_buffer, kwds)
  File "/home/airflow/.local/lib/python3.8/site-packages/pandas/io/parsers/readers.py", line 577, in _read
    parser = TextFileReader(filepath_or_buffer, **kwds)
  File "/home/airflow/.local/lib/python3.8/site-packages/pandas/io/parsers/readers.py", line 1407, in __init__
    self._engine = self._make_engine(f, self.engine)
  File "/home/airflow/.local/lib/python3.8/site-packages/pandas/io/parsers/readers.py", line 1661, in _make_engine
    self.handles = get_handle(
  File "/home/airflow/.local/lib/python3.8/site-packages/pandas/io/common.py", line 716, in get_handle
    ioargs = _get_filepath_or_buffer(
  File "/home/airflow/.local/lib/python3.8/site-packages/pandas/io/common.py", line 456, in _get_filepath_or_buffer
    raise ValueError(msg)
ValueError: Invalid file path or buffer object type: <class 'contextlib._GeneratorContextManager'>
[2025-05-03T21:55:09.911+0000] {taskinstance.py:1398} INFO - Marking task as FAILED. dag_id=gold_pipeline, task_id=transform_gold_data, execution_date=20250503T215437, start_date=20250503T215509, end_date=20250503T215509
[2025-05-03T21:55:09.931+0000] {standard_task_runner.py:104} ERROR - Failed to execute job 12 for task transform_gold_data (Invalid file path or buffer object type: <class 'contextlib._GeneratorContextManager'>; 1716)
[2025-05-03T21:55:09.974+0000] {local_task_job_runner.py:228} INFO - Task exited with return code 1
[2025-05-03T21:55:10.022+0000] {taskinstance.py:2776} INFO - 0 downstream tasks scheduled from follow-on schedule check
