[2025-05-20T11:15:21.542+0000] {taskinstance.py:1157} INFO - Dependencies all met for dep_context=non-requeueable deps ti=<TaskInstance: gold_pipelines.verify_yfinance_api manual__2025-05-20T11:15:19.535373+00:00 [queued]>
[2025-05-20T11:15:21.559+0000] {taskinstance.py:1157} INFO - Dependencies all met for dep_context=requeueable deps ti=<TaskInstance: gold_pipelines.verify_yfinance_api manual__2025-05-20T11:15:19.535373+00:00 [queued]>
[2025-05-20T11:15:21.560+0000] {taskinstance.py:1359} INFO - Starting attempt 1 of 1
[2025-05-20T11:15:21.602+0000] {taskinstance.py:1380} INFO - Executing <Task(PythonOperator): verify_yfinance_api> on 2025-05-20 11:15:19.535373+00:00
[2025-05-20T11:15:21.611+0000] {standard_task_runner.py:57} INFO - Started process 4704 to run task
[2025-05-20T11:15:21.620+0000] {standard_task_runner.py:84} INFO - Running: ['***', 'tasks', 'run', 'gold_pipelines', 'verify_yfinance_api', 'manual__2025-05-20T11:15:19.535373+00:00', '--job-id', '13', '--raw', '--subdir', 'DAGS_FOLDER/pipeline.py', '--cfg-path', '/tmp/tmpo76mmuzg']
[2025-05-20T11:15:21.626+0000] {standard_task_runner.py:85} INFO - Job 13: Subtask verify_yfinance_api
[2025-05-20T11:15:21.740+0000] {task_command.py:415} INFO - Running <TaskInstance: gold_pipelines.verify_yfinance_api manual__2025-05-20T11:15:19.535373+00:00 [running]> on host a1bf4572f1fa
[2025-05-20T11:15:21.908+0000] {taskinstance.py:1660} INFO - Exporting env vars: AIRFLOW_CTX_DAG_OWNER='***' AIRFLOW_CTX_DAG_ID='gold_pipelines' AIRFLOW_CTX_TASK_ID='verify_yfinance_api' AIRFLOW_CTX_EXECUTION_DATE='2025-05-20T11:15:19.535373+00:00' AIRFLOW_CTX_TRY_NUMBER='1' AIRFLOW_CTX_DAG_RUN_ID='manual__2025-05-20T11:15:19.535373+00:00'
[2025-05-20T11:15:22.209+0000] {taskinstance.py:1935} ERROR - Task failed with exception
Traceback (most recent call last):
  File "/opt/airflow/dags/verification.py", line 10, in check_yfinance_api
    raise Exception(f"YFinance API check failed with status: {response.status_code}")
Exception: YFinance API check failed with status: 429

During handling of the above exception, another exception occurred:

Traceback (most recent call last):
  File "/home/airflow/.local/lib/python3.8/site-packages/airflow/operators/python.py", line 192, in execute
    return_value = self.execute_callable()
  File "/home/airflow/.local/lib/python3.8/site-packages/airflow/operators/python.py", line 209, in execute_callable
    return self.python_callable(*self.op_args, **self.op_kwargs)
  File "/opt/airflow/dags/verification.py", line 12, in check_yfinance_api
    raise Exception(f"YFinance API check failed: {str(e)}")
Exception: YFinance API check failed: YFinance API check failed with status: 429
[2025-05-20T11:15:22.225+0000] {taskinstance.py:1398} INFO - Marking task as FAILED. dag_id=gold_pipelines, task_id=verify_yfinance_api, execution_date=20250520T111519, start_date=20250520T111521, end_date=20250520T111522
[2025-05-20T11:15:22.242+0000] {standard_task_runner.py:104} ERROR - Failed to execute job 13 for task verify_yfinance_api (YFinance API check failed: YFinance API check failed with status: 429; 4704)
[2025-05-20T11:15:22.276+0000] {local_task_job_runner.py:228} INFO - Task exited with return code 1
[2025-05-20T11:15:22.297+0000] {taskinstance.py:2776} INFO - 0 downstream tasks scheduled from follow-on schedule check
