[2025-05-08T13:57:54.223+0000] {taskinstance.py:1157} INFO - Dependencies all met for dep_context=non-requeueable deps ti=<TaskInstance: gold_pipeline.extract_gold_data manual__2025-05-08T13:57:39.759762+00:00 [queued]>
[2025-05-08T13:57:54.238+0000] {taskinstance.py:1157} INFO - Dependencies all met for dep_context=requeueable deps ti=<TaskInstance: gold_pipeline.extract_gold_data manual__2025-05-08T13:57:39.759762+00:00 [queued]>
[2025-05-08T13:57:54.238+0000] {taskinstance.py:1359} INFO - Starting attempt 1 of 1
[2025-05-08T13:57:54.266+0000] {taskinstance.py:1380} INFO - Executing <Task(PythonOperator): extract_gold_data> on 2025-05-08 13:57:39.759762+00:00
[2025-05-08T13:57:54.274+0000] {standard_task_runner.py:57} INFO - Started process 4602 to run task
[2025-05-08T13:57:54.281+0000] {standard_task_runner.py:84} INFO - Running: ['***', 'tasks', 'run', 'gold_pipeline', 'extract_gold_data', 'manual__2025-05-08T13:57:39.759762+00:00', '--job-id', '29', '--raw', '--subdir', 'DAGS_FOLDER/pipeline.py', '--cfg-path', '/tmp/tmp0a4qhj2o']
[2025-05-08T13:57:54.286+0000] {standard_task_runner.py:85} INFO - Job 29: Subtask extract_gold_data
[2025-05-08T13:57:54.362+0000] {task_command.py:415} INFO - Running <TaskInstance: gold_pipeline.extract_gold_data manual__2025-05-08T13:57:39.759762+00:00 [running]> on host 223a2d167166
[2025-05-08T13:57:54.503+0000] {taskinstance.py:1660} INFO - Exporting env vars: AIRFLOW_CTX_DAG_OWNER='***' AIRFLOW_CTX_DAG_ID='gold_pipeline' AIRFLOW_CTX_TASK_ID='extract_gold_data' AIRFLOW_CTX_EXECUTION_DATE='2025-05-08T13:57:39.759762+00:00' AIRFLOW_CTX_TRY_NUMBER='1' AIRFLOW_CTX_DAG_RUN_ID='manual__2025-05-08T13:57:39.759762+00:00'
[2025-05-08T13:57:57.068+0000] {logging_mixin.py:151} INFO - Aperçu des données récupérées :
[2025-05-08T13:57:57.105+0000] {logging_mixin.py:151} INFO -                    raw_date source_name  ... volume         ingestion_timestamp
0 2025-04-08 00:00:00-04:00    yfinance  ...  18916  2025-05-08T13:57:57.049491
1 2025-04-08 04:00:00-04:00    yfinance  ...  27702  2025-05-08T13:57:57.049599
2 2025-04-08 08:00:00-04:00    yfinance  ...  63689  2025-05-08T13:57:57.049672
3 2025-04-08 12:00:00-04:00    yfinance  ...  47138  2025-05-08T13:57:57.049741
4 2025-04-08 16:00:00-04:00    yfinance  ...   8421  2025-05-08T13:57:57.049811

[5 rows x 7 columns]
[2025-05-08T13:57:58.196+0000] {client.py:496} INFO - Writing to '/gold_datalake/raw/gold_prices/2025-05-08.csv'.
[2025-05-08T13:57:58.243+0000] {util.py:78} ERROR - Exception in child.
Traceback (most recent call last):
  File "/home/airflow/.local/lib/python3.8/site-packages/hdfs/util.py", line 76, in consumer
    self._consumer(data)
  File "/home/airflow/.local/lib/python3.8/site-packages/hdfs/client.py", line 515, in consumer
    raise _to_error(res)
hdfs.util.HdfsError: /gold_datalake/raw/gold_prices/2025-05-08.csv for client 172.18.0.8 already exists
	at org.apache.hadoop.hdfs.server.namenode.FSDirWriteFileOp.startFile(FSDirWriteFileOp.java:388)
	at org.apache.hadoop.hdfs.server.namenode.FSNamesystem.startFileInt(FSNamesystem.java:2536)
	at org.apache.hadoop.hdfs.server.namenode.FSNamesystem.startFile(FSNamesystem.java:2433)
	at org.apache.hadoop.hdfs.server.namenode.NameNodeRpcServer.create(NameNodeRpcServer.java:791)
	at org.apache.hadoop.hdfs.protocolPB.ClientNamenodeProtocolServerSideTranslatorPB.create(ClientNamenodeProtocolServerSideTranslatorPB.java:475)
	at org.apache.hadoop.hdfs.protocol.proto.ClientNamenodeProtocolProtos$ClientNamenodeProtocol$2.callBlockingMethod(ClientNamenodeProtocolProtos.java)
	at org.apache.hadoop.ipc.ProtobufRpcEngine$Server$ProtoBufRpcInvoker.call(ProtobufRpcEngine.java:528)
	at org.apache.hadoop.ipc.RPC$Server.call(RPC.java:1070)
	at org.apache.hadoop.ipc.Server$RpcCall.run(Server.java:999)
	at org.apache.hadoop.ipc.Server$RpcCall.run(Server.java:927)
	at java.security.AccessController.doPrivileged(Native Method)
	at javax.security.auth.Subject.doAs(Subject.java:422)
	at org.apache.hadoop.security.UserGroupInformation.doAs(UserGroupInformation.java:1730)
	at org.apache.hadoop.ipc.Server$Handler.run(Server.java:2915)

[2025-05-08T13:57:58.249+0000] {taskinstance.py:1935} ERROR - Task failed with exception
Traceback (most recent call last):
  File "/home/airflow/.local/lib/python3.8/site-packages/airflow/operators/python.py", line 192, in execute
    return_value = self.execute_callable()
  File "/home/airflow/.local/lib/python3.8/site-packages/airflow/operators/python.py", line 209, in execute_callable
    return self.python_callable(*self.op_args, **self.op_kwargs)
  File "/opt/airflow/dags/extract_gold.py", line 87, in extract_gold_data
    x.to_csv(writer, index=False)
  File "/home/airflow/.local/lib/python3.8/site-packages/hdfs/util.py", line 104, in __exit__
    raise self._err # pylint: disable=raising-bad-type
  File "/home/airflow/.local/lib/python3.8/site-packages/hdfs/util.py", line 76, in consumer
    self._consumer(data)
  File "/home/airflow/.local/lib/python3.8/site-packages/hdfs/client.py", line 515, in consumer
    raise _to_error(res)
hdfs.util.HdfsError: /gold_datalake/raw/gold_prices/2025-05-08.csv for client 172.18.0.8 already exists
	at org.apache.hadoop.hdfs.server.namenode.FSDirWriteFileOp.startFile(FSDirWriteFileOp.java:388)
	at org.apache.hadoop.hdfs.server.namenode.FSNamesystem.startFileInt(FSNamesystem.java:2536)
	at org.apache.hadoop.hdfs.server.namenode.FSNamesystem.startFile(FSNamesystem.java:2433)
	at org.apache.hadoop.hdfs.server.namenode.NameNodeRpcServer.create(NameNodeRpcServer.java:791)
	at org.apache.hadoop.hdfs.protocolPB.ClientNamenodeProtocolServerSideTranslatorPB.create(ClientNamenodeProtocolServerSideTranslatorPB.java:475)
	at org.apache.hadoop.hdfs.protocol.proto.ClientNamenodeProtocolProtos$ClientNamenodeProtocol$2.callBlockingMethod(ClientNamenodeProtocolProtos.java)
	at org.apache.hadoop.ipc.ProtobufRpcEngine$Server$ProtoBufRpcInvoker.call(ProtobufRpcEngine.java:528)
	at org.apache.hadoop.ipc.RPC$Server.call(RPC.java:1070)
	at org.apache.hadoop.ipc.Server$RpcCall.run(Server.java:999)
	at org.apache.hadoop.ipc.Server$RpcCall.run(Server.java:927)
	at java.security.AccessController.doPrivileged(Native Method)
	at javax.security.auth.Subject.doAs(Subject.java:422)
	at org.apache.hadoop.security.UserGroupInformation.doAs(UserGroupInformation.java:1730)
	at org.apache.hadoop.ipc.Server$Handler.run(Server.java:2915)

[2025-05-08T13:57:58.272+0000] {taskinstance.py:1398} INFO - Marking task as FAILED. dag_id=gold_pipeline, task_id=extract_gold_data, execution_date=20250508T135739, start_date=20250508T135754, end_date=20250508T135758
[2025-05-08T13:57:58.307+0000] {standard_task_runner.py:104} ERROR - Failed to execute job 29 for task extract_gold_data (/gold_datalake/raw/gold_prices/2025-05-08.csv for client 172.18.0.8 already exists
	at org.apache.hadoop.hdfs.server.namenode.FSDirWriteFileOp.startFile(FSDirWriteFileOp.java:388)
	at org.apache.hadoop.hdfs.server.namenode.FSNamesystem.startFileInt(FSNamesystem.java:2536)
	at org.apache.hadoop.hdfs.server.namenode.FSNamesystem.startFile(FSNamesystem.java:2433)
	at org.apache.hadoop.hdfs.server.namenode.NameNodeRpcServer.create(NameNodeRpcServer.java:791)
	at org.apache.hadoop.hdfs.protocolPB.ClientNamenodeProtocolServerSideTranslatorPB.create(ClientNamenodeProtocolServerSideTranslatorPB.java:475)
	at org.apache.hadoop.hdfs.protocol.proto.ClientNamenodeProtocolProtos$ClientNamenodeProtocol$2.callBlockingMethod(ClientNamenodeProtocolProtos.java)
	at org.apache.hadoop.ipc.ProtobufRpcEngine$Server$ProtoBufRpcInvoker.call(ProtobufRpcEngine.java:528)
	at org.apache.hadoop.ipc.RPC$Server.call(RPC.java:1070)
	at org.apache.hadoop.ipc.Server$RpcCall.run(Server.java:999)
	at org.apache.hadoop.ipc.Server$RpcCall.run(Server.java:927)
	at java.security.AccessController.doPrivileged(Native Method)
	at javax.security.auth.Subject.doAs(Subject.java:422)
	at org.apache.hadoop.security.UserGroupInformation.doAs(UserGroupInformation.java:1730)
	at org.apache.hadoop.ipc.Server$Handler.run(Server.java:2915)
; 4602)
[2025-05-08T13:57:58.342+0000] {local_task_job_runner.py:228} INFO - Task exited with return code 1
[2025-05-08T13:57:58.399+0000] {taskinstance.py:2776} INFO - 0 downstream tasks scheduled from follow-on schedule check
